/var/spool/slurmd/job333963/slurm_script: line 25: /home/ids/jpabon/anaconda3/etc/profile.d/conda.sh: No such file or directory

CondaError: Run 'conda init' before 'conda activate'


A module that was compiled using NumPy 1.x cannot be run in
NumPy 2.2.5 as it may crash. To support both 1.x and 2.x
versions of NumPy, modules must be compiled with NumPy 2.0.
Some module may need to rebuild instead e.g. with 'pybind11>=2.12'.

If you are a user of the module, the easiest solution will be to
downgrade to 'numpy<2' or try to upgrade the affected module.
We expect that some modules will need time to support NumPy 2.

Traceback (most recent call last):  File "/home/ids/jpabon/projects/clip_odg/main.py", line 2, in <module>
    import torch
  File "/home/ids/jpabon/miniconda3/envs/clip_odg/lib/python3.10/site-packages/torch/__init__.py", line 1382, in <module>
    from .functional import *  # noqa: F403
  File "/home/ids/jpabon/miniconda3/envs/clip_odg/lib/python3.10/site-packages/torch/functional.py", line 7, in <module>
    import torch.nn.functional as F
  File "/home/ids/jpabon/miniconda3/envs/clip_odg/lib/python3.10/site-packages/torch/nn/__init__.py", line 1, in <module>
    from .modules import *  # noqa: F403
  File "/home/ids/jpabon/miniconda3/envs/clip_odg/lib/python3.10/site-packages/torch/nn/modules/__init__.py", line 35, in <module>
    from .transformer import TransformerEncoder, TransformerDecoder, \
  File "/home/ids/jpabon/miniconda3/envs/clip_odg/lib/python3.10/site-packages/torch/nn/modules/transformer.py", line 20, in <module>
    device: torch.device = torch.device(torch._C._get_default_device()),  # torch.device('cpu'),
/home/ids/jpabon/miniconda3/envs/clip_odg/lib/python3.10/site-packages/torch/nn/modules/transformer.py:20: UserWarning: Failed to initialize NumPy: _ARRAY_API not found (Triggered internally at /opt/conda/conda-bld/pytorch_1695392020201/work/torch/csrc/utils/tensor_numpy.cpp:84.)
  device: torch.device = torch.device(torch._C._get_default_device()),  # torch.device('cpu'),
/home/ids/jpabon/miniconda3/envs/clip_odg/lib/python3.10/site-packages/requests/__init__.py:86: RequestsDependencyWarning: Unable to find acceptable character detection dependency (chardet or charset_normalizer).
  warnings.warn(
Traceback (most recent call last):
  File "/home/ids/jpabon/miniconda3/envs/clip_odg/lib/python3.10/site-packages/huggingface_hub/utils/_http.py", line 409, in hf_raise_for_status
    response.raise_for_status()
  File "/home/ids/jpabon/miniconda3/envs/clip_odg/lib/python3.10/site-packages/requests/models.py", line 1024, in raise_for_status
    raise HTTPError(http_error_msg, response=self)
requests.exceptions.HTTPError: 404 Client Error: Not Found for url: https://huggingface.co/ViT-B/16/resolve/main/config.json

The above exception was the direct cause of the following exception:

Traceback (most recent call last):
  File "/home/ids/jpabon/miniconda3/envs/clip_odg/lib/python3.10/site-packages/transformers/utils/hub.py", line 424, in cached_files
    hf_hub_download(
  File "/home/ids/jpabon/miniconda3/envs/clip_odg/lib/python3.10/site-packages/huggingface_hub/utils/_validators.py", line 114, in _inner_fn
    return fn(*args, **kwargs)
  File "/home/ids/jpabon/miniconda3/envs/clip_odg/lib/python3.10/site-packages/huggingface_hub/file_download.py", line 1008, in hf_hub_download
    return _hf_hub_download_to_cache_dir(
  File "/home/ids/jpabon/miniconda3/envs/clip_odg/lib/python3.10/site-packages/huggingface_hub/file_download.py", line 1115, in _hf_hub_download_to_cache_dir
    _raise_on_head_call_error(head_call_error, force_download, local_files_only)
  File "/home/ids/jpabon/miniconda3/envs/clip_odg/lib/python3.10/site-packages/huggingface_hub/file_download.py", line 1643, in _raise_on_head_call_error
    raise head_call_error
  File "/home/ids/jpabon/miniconda3/envs/clip_odg/lib/python3.10/site-packages/huggingface_hub/file_download.py", line 1531, in _get_metadata_or_catch_error
    metadata = get_hf_file_metadata(
  File "/home/ids/jpabon/miniconda3/envs/clip_odg/lib/python3.10/site-packages/huggingface_hub/utils/_validators.py", line 114, in _inner_fn
    return fn(*args, **kwargs)
  File "/home/ids/jpabon/miniconda3/envs/clip_odg/lib/python3.10/site-packages/huggingface_hub/file_download.py", line 1448, in get_hf_file_metadata
    r = _request_wrapper(
  File "/home/ids/jpabon/miniconda3/envs/clip_odg/lib/python3.10/site-packages/huggingface_hub/file_download.py", line 286, in _request_wrapper
    response = _request_wrapper(
  File "/home/ids/jpabon/miniconda3/envs/clip_odg/lib/python3.10/site-packages/huggingface_hub/file_download.py", line 310, in _request_wrapper
    hf_raise_for_status(response)
  File "/home/ids/jpabon/miniconda3/envs/clip_odg/lib/python3.10/site-packages/huggingface_hub/utils/_http.py", line 459, in hf_raise_for_status
    raise _format(RepositoryNotFoundError, message, response) from e
huggingface_hub.errors.RepositoryNotFoundError: 404 Client Error. (Request ID: Root=1-68235788-4c566f7140f2203b557b6da6;ebc67dc3-e07d-47b3-9698-57a0282c5121)

Repository Not Found for url: https://huggingface.co/ViT-B/16/resolve/main/config.json.
Please make sure you specified the correct `repo_id` and `repo_type`.
If you are trying to access a private or gated repo, make sure you are authenticated. For more details, see https://huggingface.co/docs/huggingface_hub/authentication

The above exception was the direct cause of the following exception:

Traceback (most recent call last):
  File "/home/ids/jpabon/projects/clip_odg/main.py", line 172, in <module>
    main() 
  File "/home/ids/jpabon/projects/clip_odg/main.py", line 106, in main
    original_model = PrunedCLIP.get_original_clip(args.model_name)
  File "/home/ids/jpabon/projects/clip_odg/models/pruned_clip.py", line 61, in get_original_clip
    return cls(model_name=model_name, prune_vision_layers=None)
  File "/home/ids/jpabon/projects/clip_odg/models/pruned_clip.py", line 27, in __init__
    self.clip = CLIPModel.from_pretrained(model_name)
  File "/home/ids/jpabon/miniconda3/envs/clip_odg/lib/python3.10/site-packages/transformers/modeling_utils.py", line 279, in _wrapper
    return func(*args, **kwargs)
  File "/home/ids/jpabon/miniconda3/envs/clip_odg/lib/python3.10/site-packages/transformers/modeling_utils.py", line 4078, in from_pretrained
    resolved_config_file = cached_file(
  File "/home/ids/jpabon/miniconda3/envs/clip_odg/lib/python3.10/site-packages/transformers/utils/hub.py", line 266, in cached_file
    file = cached_files(path_or_repo_id=path_or_repo_id, filenames=[filename], **kwargs)
  File "/home/ids/jpabon/miniconda3/envs/clip_odg/lib/python3.10/site-packages/transformers/utils/hub.py", line 456, in cached_files
    raise OSError(
OSError: ViT-B/16 is not a local folder and is not a valid model identifier listed on 'https://huggingface.co/models'
If this is a private repository, make sure to pass a token having permission to this repo either by logging in with `huggingface-cli login` or by passing `token=<your_token>`
srun: error: nodemm06: task 0: Exited with exit code 1
